<?xml version="1.0"?>
<robot name="open_manipulator_y">

  <!-- Base -->
  <link name="base_link"/>

  <!-- Arm Chain -->
  <link name="link1">
    <inertial>
      <origin xyz="0 0 0" rpy="0 0 0"/>
      <mass value="1.0"/>
      <inertia ixx="0.002" iyy="0.002" izz="0.002" ixy="0" ixz="0" iyz="0"/>
    </inertial>
  </link>
  <joint name="joint1" type="revolute">
    <parent link="base_link"/>
    <child link="link1"/>
    <origin xyz="0 0 0.1715" rpy="0 0 0"/>
    <axis xyz="0 0 1"/>
    <limit lower="-6.28319" upper="6.28319" effort="200" velocity="6.28319"/>
  </joint>

  <link name="link2">
    <inertial>
      <origin xyz="0 0 0" rpy="0 0 0"/>
      <mass value="1.2"/>
      <inertia ixx="0.003" iyy="0.003" izz="0.003" ixy="0" ixz="0" iyz="0"/>
    </inertial>
  </link>
  <joint name="joint2" type="revolute">
    <parent link="link1"/>
    <child link="link2"/>
    <origin xyz="0 -0.1215 0" rpy="0 0 0"/>
    <axis xyz="0 1 0"/>
    <limit lower="-6.28319" upper="6.28319" effort="200" velocity="6.28319"/>
  </joint>

  <link name="link3">
    <inertial>
      <origin xyz="0 0 0" rpy="0 0 0"/>
      <mass value="1.5"/>
      <inertia ixx="0.004" iyy="0.004" izz="0.004" ixy="0" ixz="0" iyz="0"/>
    </inertial>
  </link>
  <joint name="joint3" type="revolute">
    <parent link="link2"/>
    <child link="link3"/>
    <origin xyz="0 0 0.247" rpy="0 0 0"/>
    <axis xyz="0 1 0"/>
    <limit lower="-6.28319" upper="6.28319" effort="200" velocity="6.28319"/>
  </joint>

  <link name="link4">
    <inertial>
      <origin xyz="0 0 0" rpy="0 0 0"/>
      <mass value="1.0"/>
      <inertia ixx="0.002" iyy="0.002" izz="0.002" ixy="0" ixz="0" iyz="0"/>
    </inertial>
  </link>
  <joint name="joint4" type="revolute">
    <parent link="link3"/>
    <child link="link4"/>
    <origin xyz="0 0.1215 0.2195" rpy="0 0 0"/>
    <axis xyz="0 1 0"/>
    <limit lower="-6.28319" upper="6.28319" effort="200" velocity="6.28319"/>
  </joint>

  <link name="link5">
    <inertial>
      <origin xyz="0 0 0" rpy="0 0 0"/>
      <mass value="0.8"/>
      <inertia ixx="0.0015" iyy="0.0015" izz="0.0015" ixy="0" ixz="0" iyz="0"/>
    </inertial>
  </link>
  <joint name="joint5" type="revolute">
    <parent link="link4"/>
    <child link="link5"/>
    <origin xyz="0 -0.113 0" rpy="0 0 0"/>
    <axis xyz="0 0 1"/>
    <limit lower="-6.28319" upper="6.28319" effort="200" velocity="6.28319"/>
  </joint>

  <link name="link6">
    <inertial>
      <origin xyz="0 0 0" rpy="0 0 0"/>
      <mass value="0.6"/>
      <inertia ixx="0.001" iyy="0.001" izz="0.001" ixy="0" ixz="0" iyz="0"/>
    </inertial>
  </link>
  <joint name="joint6" type="revolute">
    <parent link="link5"/>
    <child link="link6"/>
    <origin xyz="0 0 0.1155" rpy="0 0 0"/>
    <axis xyz="0 1 0"/>
    <limit lower="-6.28319" upper="6.28319" effort="200" velocity="6.28319"/>
  </joint>

<link name="cleaning_pad"/>
  <joint name="pad_fixed" type="fixed">
    <parent link="link6"/>
    <child link="cleaning_pad"/>
    <origin xyz="0 -0.235 -0.018" rpy="0 0 0"/>
  </joint>

<link name="tcp_link"/>
  <joint name="tcp_fixed" type="fixed">
    <parent link="cleaning_pad"/>
    <child link="tcp_link"/>
    <origin xyz="0 0 0" rpy="0 0 0"/>
  </joint>

  </robot>
  <!-- Gripper Right Finger -->
  <link name="rh_r1"/>
  <joint name="rh_r1_joint" type="revolute">
    <parent link="flange"/>
    <child link="rh_r1"/>
    <origin xyz="0.00803822 -0.156994 0.0000064" rpy="0 0 0"/>
    <axis xyz="1 0 0"/>
    <limit lower="0" upper="1.1" effort="100" velocity="1.0"/>
  </joint>

  <link name="rh_r2"/>
  <joint name="rh_r2_joint" type="revolute">
    <parent link="rh_r1"/>
    <child link="rh_r2"/>
    <origin xyz="0 0.0493634 0.0285" rpy="0 0 0"/>
    <axis xyz="-1 0 0"/>
    <limit lower="0" upper="1.0" effort="100" velocity="1.0"/>
  </joint>

  <!-- Gripper Left Finger -->
  <link name="rh_l1"/>
  <joint name="rh_l1_joint" type="revolute">
    <parent link="flange"/>
    <child link="rh_l1"/>
    <origin xyz="-0.00796177 -0.157006 -0.0000063" rpy="0 0 0"/>
    <axis xyz="-1 0 0"/>
    <limit lower="0" upper="1.1" effort="100" velocity="1.0"/>
  </joint>

  <link name="rh_l2"/>
  <joint name="rh_l2_joint" type="revolute">
    <parent link="rh_l1"/>
    <child link="rh_l2"/>
    <origin xyz="0 -0.0493634 0.0285" rpy="0 0 0"/>
    <axis xyz="1 0 0"/>
    <limit lower="0" upper="1.0" effort="100" velocity="1.0"/>
  </joint>

</robot>

