<mujoco model="open_manipulator_y">
  <compiler angle="radian" meshdir="assets" autolimits="true"/>

  <option integrator="implicitfast" timestep="0.002" gravity="0 0 -9.81"/>

  <default>
    <default class="Y">
      <joint range="-6.28319 6.28319" armature="0.1" damping="0.5"/>
    </default>
  </default>

  <asset>
    <mesh name="base_unit" file="base_unit.stl" scale="0.001 0.001 0.001"/>
    <mesh name="link1" file="link1.stl" scale="0.001 0.001 0.001"/>
    <mesh name="link2" file="link2.stl" scale="0.001 0.001 0.001"/>
    <mesh name="link3" file="link3.stl" scale="0.001 0.001 0.001"/>
    <mesh name="link4" file="link4.stl" scale="0.001 0.001 0.001"/>
    <mesh name="link5" file="link5.stl" scale="0.001 0.001 0.001"/>
    <mesh name="link6" file="link6.stl" scale="0.001 0.001 0.001"/>
    <mesh name="flange" file="flange.stl" scale="0.001 0.001 0.001"/>
    <mesh name="base" file="base.stl" scale="0.001 0.001 0.001"/>
  </asset>

  <worldbody>
    <geom type="mesh" rgba="0.2 0.2 0.2 1" mesh="base_unit"/>
    <body name="link1" pos="0 0 0.1715">
      <inertial pos="-0.000110636 -0.00547113 -0.0158977" quat="0.98558 0.168758 -0.00294757 0.0120358" mass="2.06488" diaginertia="0.00303337 0.00279081 0.00221937"/>
      <joint name="joint1" pos="0 0 0" axis="0 0 1" class="Y"/>
      <geom type="mesh" rgba="0.2 0.2 0.2 1" mesh="link1"/>
      <body name="link2" pos="0 -0.1215 0">
        <inertial pos="1.14054e-05 0.0161842 0.103606" quat="0.999988 -0.00477885 -0.000609836 0.00067321" mass="3.67954" diaginertia="0.051732 0.0503576 0.00449718"/>
        <joint name="joint2" pos="0 0 0" axis="0 1 0" class="Y"/>
        <geom type="mesh" rgba="0.2 0.2 0.2 1" mesh="link2"/>
        <body name="link3" pos="0 0 0.247">
          <inertial pos="7.81487e-05 0.107185 0.141173" quat="0.999987 0.00500823 0.000469041 -0.00072733" mass="2.38659" diaginertia="0.0226944 0.021922 0.00277422"/>
          <joint name="joint3" pos="0 0 0" axis="0 1 0" class="Y"/>
          <geom type="mesh" rgba="0.2 0.2 0.2 1" mesh="link3"/>
          <body name="link4" pos="0 0.1215 0.2195">
            <inertial pos="-0.000133183 -0.107467 0.0190907" quat="0.983636 0.179196 0.00338061 -0.0183488" mass="1.40023" diaginertia="0.00175475 0.00162284 0.00115817"/>
            <joint name="joint4" pos="0 0 0" axis="0 1 0" class="Y"/>
            <geom type="mesh" rgba="0.2 0.2 0.2 1" mesh="link4"/>
            <body name="link5" pos="0 -0.113 0">
              <inertial pos="0.000133183 -0.0190907 0.109967" quat="0.822247 0.568825 0.0105841 -0.015365" mass="1.40023" diaginertia="0.00175475 0.00162284 0.00115817"/>
              <joint name="joint5" pos="0 0 0" axis="0 0 1" class="Y"/>
              <geom type="mesh" rgba="0.2 0.2 0.2 1" mesh="link5"/>
              <body name="link6" pos="0 0 0.1155">
                <inertial pos="1.6005e-05 -0.103085 0.00570277" quat="0.456875 0.889528 0.00170634 -0.00130773" mass="0.652774" diaginertia="0.00112656 0.000847594 0.000551829"/>
                <joint name="joint6" pos="0 0 0" axis="0 1 0" class="Y"/>
                <geom type="mesh" rgba="0.2 0.2 0.2 1" mesh="link6"/>
                <geom pos="0 -0.103 0" quat="1 0 0 0" type="mesh" rgba="0.2 0.2 0.2 1" mesh="flange"/>
                <geom pos="0 -0.109 0" quat="0.500398 0.5 0.5 -0.499602" type="mesh" mesh="base"/>
                <site name="tcp_link" pos="0.0 0.0 0.0" size="0.005" rgba="1 0 0 1"/>            
              </body>
            </body>
          </body>
        </body>
      </body>
    </body>
  </worldbody>

  <contact>
    <exclude body1="world" body2="link1"/>
  </contact>

  <actuator>
  <!--보통은 "제어 입력을 전류[A]" 단위로 직접 집어넣고 싶을 때 gear에 Kt × G × η를 넣어줌. 
  그러면 Mujoco가 내부에서 자동으로 토크로 변환해줌-->
  
    <motor name="actuator_joint1" joint="joint1" gear="1" ctrllimited="true" ctrlrange="-10 10"/>
    <motor name="actuator_joint2" joint="joint2" gear="1" ctrllimited="true" ctrlrange="-10 10"/>
    <motor name="actuator_joint3" joint="joint3" gear="1" ctrllimited="true" ctrlrange="-10 10"/>
    <motor name="actuator_joint4" joint="joint4" gear="1" ctrllimited="true" ctrlrange="-10 10"/>
    <motor name="actuator_joint5" joint="joint5" gear="1" ctrllimited="true" ctrlrange="-10 10"/>
    <motor name="actuator_joint6" joint="joint6" gear="1" ctrllimited="true" ctrlrange="-10 10"/>

  </actuator>

</mujoco>
